Workbook
Name arc_fem: RanksChart!$CN$1:$CO$77
Name arc_masc: RanksChart!$AX$1:$AY$90
Name bad_fem: RanksChart!$BM$1:$BN$23
Name bad_masc: RanksChart!$W$1:$X$23
Name bal_fem: RanksChart!$CH$1:$CI$17
Name bal_masc: RanksChart!$AR$1:$AS$18
Name bas_fem: RanksChart!$BG$1:$BH$121
Name bas_masc: RanksChart!$Q$1:$R$160
Name bes_fem: RanksChart!$BJ$1:$BK$30
Name bes_masc: RanksChart!$T$1:$U$84
Name cur_fem: RanksChart!$BP$1:$BQ$48
Name cur_masc: RanksChart!$Z$1:$AA$62
Name esg_fem: RanksChart!$CQ$1:$CR$59
Name esg_masc: RanksChart!$BA$1:$BB$74
Name fts_fem: RanksChart!$K$1:$L$92
Name fts_masc: RanksChart!$H$1:$I$140
Name fut_fem: RanksChart!$E$1:$F$199
Name fut_masc: RanksChart!$B$1:$C$211
Name hck_fem: RanksChart!$CK$1:$CL$84
Name hck_masc: RanksChart!$AU$1:$AV$101
Name national_teams: NationalTeams!$B$3:$C$448
Name rug_fem: RanksChart!$BV$1:$BW$69
Name rug_masc: RanksChart!$AF$1:$AG$114
Name sqs_fem: RanksChart!$BY$1:$BZ$19
Name sqs_masc: RanksChart!$AI$1:$AJ$23
Name tem_fem: RanksChart!$CE$1:$CF$61
Name tem_masc: RanksChart!$AO$1:$AP$67
Name ten_fem: RanksChart!$BS$1:$BT$48
Name ten_masc: RanksChart!$AC$1:$AD$49
Name vlp_fem: RanksChart!$CB$1:$CC$53
Name vlp_masc: RanksChart!$AL$1:$AM$59
Name vol_fem: RanksChart!$BD$1:$BE$89
Name vol_masc: RanksChart!$N$1:$O$101

Sheet NationalTeams
B1: NationalTeams | S1: INSERT INTO | T1: VALUES | U1: ( | V1: ) | W1: " | X1: ' | Y1: , | Z1: ;
B2: team_id | C2: team_name | E2: team_type | F2: rank | I2: E:\imagenes | J2: region | K2: team_region_id | L2: ruta_b | M2: team_flag | N2: ruta_e | O2: team_shield | P2: country | Q2: ol_country_id | S2: pg_read_binary_file
B3: 1 | C3: Afganistan | E3: M | G3: 52 | H3: 56 | I3: 56 | J3: Asia | K3: =INDEX(TeamRegion!B:B,MATCH(J3,TeamRegion!C:C,0)) -> 2 | L3: \banderas\afganistan.jpg | M3: =_xlfn.CONCAT($I$2,L3) -> E:\imagenes\banderas\afganistan.jpg | N3: \escudos\afganistan.png | O3: =_xlfn.CONCAT($I$2,N3) -> E:\imagenes\escudos\afganistan.png | P3: Dinazor | Q3: =INDEX(PlayerCountry!B:B,MATCH(P3,PlayerCountry!C:C,0)) -> 2 | S3: =_xlfn.CONCAT($S$1,$W$1,$B$1,$W$1," ",$U$1,$C$2,$Y$1,$E$2,$Y$1,$K$2,$Y$1,$M$2,$Y$1,$O$2,$Y$1,$Q$2,$V$1,$T$1,$U$1,$X$1,C3,$X$1,$Y$1,$X$1,E3,$X$1,$Y$1,K3,$Y$1,$S$2,$U$1,$X$1,M3,$X$1,$V$1,$Y$1,$S$2,$U$1,$X$1,O3,$X$1,$V$1,$Y$1,Q3,$V$1,$Z$1) -> INSERT INTO "NationalTeams" (team_name,team_type,team_region_id,team_flag,team_shield,ol_country_id) VALUES ('Afganistan','M',2,pg_read_binary_file('E:\imagenes\banderas\afganistan.jpg'),pg_read_binary_file('E:\imagenes\escudos\afganistan.png'),2);
B4: 2 | C4: Africa Stars | E4: M | G4: 75 | H4: 71 | I4: 74 | J4: Africa | K4: =INDEX(TeamRegion!B:B,MATCH(J4,TeamRegion!C:C,0)) -> 1 | L4: \banderas\africa stars.png | M4: =_xlfn.CONCAT($I$2,L4) -> E:\imagenes\banderas\africa stars.png | N4: \escudos\africa stars.png | O4: =_xlfn.CONCAT($I$2,N4) -> E:\imagenes\escudos\africa stars.png | P4: Igra | Q4: =INDEX(PlayerCountry!B:B,MATCH(P4,PlayerCountry!C:C,0)) -> 3 | S4: =_xlfn.CONCAT($S$1,$W$1,$B$1,$W$1," ",$U$1,$C$2,$Y$1,$E$2,$Y$1,$K$2,$Y$1,$M$2,$Y$1,$O$2,$Y$1,$Q$2,$V$1,$T$1,$U$1,$X$1,C4,$X$1,$Y$1,$X$1,E4,$X$1,$Y$1,K4,$Y$1,$S$2,$U$1,$X$1,M4,$X$1,$V$1,$Y$1,$S$2,$U$1,$X$1,O4,$X$1,$V$1,$Y$1,Q4,$V$1,$Z$1) -> INSERT INTO "NationalTeams" (team_name,team_type,team_region_id,team_flag,team_shield,ol_country_id) VALUES ('Africa Stars','M',1,pg_read_binary_file('E:\imagenes\banderas\africa stars.png'),pg_read_binary_file('E:\imagenes\escudos\africa stars.png'),3);
B5: 3 | C5: Albania | E5: M | G5: 75 | H5: 66 | I5: 65 | J5: Europa | K5: =INDEX(TeamRegion!B:B,MATCH(J5,TeamRegion!C:C,0)) -> 4 | L5: \banderas\albania.jpg | M5: =_xlfn.CONCAT($I$2,L5) -> E:\imagenes\banderas\albania.jpg | N5: \escudos\albania.png | O5: =_xlfn.CONCAT($I$2,N5) -> E:\imagenes\escudos\albania.png | P5: Dinazor | Q5: =INDEX(PlayerCountry!B:B,MATCH(P5,PlayerCountry!C:C,0)) -> 2 | S5: =_xlfn.CONCAT($S$1,$W$1,$B$1,$W$1," ",$U$1,$C$2,$Y$1,$E$2,$Y$1,$K$2,$Y$1,$M$2,$Y$1,$O$2,$Y$1,$Q$2,$V$1,$T$1,$U$1,$X$1,C5,$X$1,$Y$1,$X$1,E5,$X$1,$Y$1,K5,$Y$1,$S$2,$U$1,$X$1,M5,$X$1,$V$1,$Y$1,$S$2,$U$1,$X$1,O5,$X$1,$V$1,$Y$1,Q5,$V$1,$Z$1) -> INSERT INTO "NationalTeams" (team_name,team_type,team_region_id,team_flag,team_shield,ol_country_id) VALUES ('Albania','M',4,pg_read_binary_file('E:\imagenes\banderas\albania.jpg'),pg_read_binary_file('E:\imagenes\escudos\albania.png'),2);
B6: 4 | C6: Alemania | E6: M | G6: 85 | H6: 87 | I6: 84 | J6: Europa | K6: =INDEX(TeamRegion!B:B,MATCH(J6,TeamRegion!C:C,0)) -> 4 | L6: \banderas\alemania.jpg | M6: =_xlfn.CONCAT($I$2,L6) -> E:\imagenes\banderas\alemania.jpg | N6: \escudos\alemania.png | O6: =_xlfn.CONCAT($I$2,N6) -> E:\imagenes\escudos\alemania.png | P6: Dinazor | Q6: =INDEX(PlayerCountry!B:B,MATCH(P6,PlayerCountry!C:C,0)) -> 2 | S6: =_xlfn.CONCAT($S$1,$W$1,$B$1,$W$1," ",$U$1,$C$2,$Y$1,$E$2,$Y$1,$K$2,$Y$1,$M$2,$Y$1,$O$2,$Y$1,$Q$2,$V$1,$T$1,$U$1,$X$1,C6,$X$1,$Y$1,$X$1,E6,$X$1,$Y$1,K6,$Y$1,$S$2,$U$1,$X$1,M6,$X$1,$V$1,$Y$1,$S$2,$U$1,$X$1,O6,$X$1,$V$1,$Y$1,Q6,$V$1,$Z$1) -> INSERT INTO "NationalTeams" (team_name,team_type,team_region_id,team_flag,team_shield,ol_country_id) VALUES ('Alemania','M',4,pg_read_binary_file('E:\imagenes\banderas\alemania.jpg'),pg_read_binary_file('E:\imagenes\escudos\alemania.png'),2);
B7: 5 | C7: America Stars | E7: M | G7: 76 | H7: 77 | I7: 78 | J7: America | K7: =INDEX(TeamRegion!B:B,MATCH(J7,TeamRegion!C:C,0)) -> 3 | L7: \banderas\america stars.png | M7: =_xlfn.CONCAT($I$2,L7) -> E:\imagenes\banderas\america stars.png | N7: \escudos\america stars.png | O7: =_xlfn.CONCAT($I$2,N7) -> E:\imagenes\escudos\america stars.png | P7: Dinazor | Q7: =INDEX(PlayerCountry!B:B,MATCH(P7,PlayerCountry!C:C,0)) -> 2 | S7: =_xlfn.CONCAT($S$1,$W$1,$B$1,$W$1," ",$U$1,$C$2,$Y$1,$E$2,$Y$1,$K$2,$Y$1,$M$2,$Y$1,$O$2,$Y$1,$Q$2,$V$1,$T$1,$U$1,$X$1,C7,$X$1,$Y$1,$X$1,E7,$X$1,$Y$1,K7,$Y$1,$S$2,$U$1,$X$1,M7,$X$1,$V$1,$Y$1,$S$2,$U$1,$X$1,O7,$X$1,$V$1,$Y$1,Q7,$V$1,$Z$1) -> INSERT INTO "NationalTeams" (team_name,team_type,team_region_id,team_flag,team_shield,ol_country_id) VALUES ('America Stars','M',3,pg_read_binary_file('E:\imagenes\banderas\america stars.png'),pg_read_binary_file('E:\imagenes\escudos\america stars.png'),2);
B8: 6 | C8: Andorra | E8: M | G8: 56 | H8: 53 | I8: 54 | J8: Europa | K8: =INDEX(TeamRegion!B:B,MATCH(J8,TeamRegion!C:C,0)) -> 4 | L8: \banderas\andorra.jpg | M8: =_xlfn.CONCAT($I$2,L8) -> E:\imagenes\banderas\andorra.jpg | N8: \escudos\andorra.png | O8: =_xlfn.CONCAT($I$2,N8) -> E:\imagenes\escudos\andorra.png | P8: Bollstam | Q8: =INDEX(PlayerCountry!B:B,MATCH(P8,PlayerCountry!C:C,0)) -> 1 | S8: =_xlfn.CONCAT($S$1,$W$1,$B$1,$W$1," ",$U$1,$C$2,$Y$1,$E$2,$Y$1,$K$2,$Y$1,$M$2,$Y$1,$O$2,$Y$1,$Q$2,$V$1,$T$1,$U$1,$X$1,C8,$X$1,$Y$1,$X$1,E8,$X$1,$Y$1,K8,$Y$1,$S$2,$U$1,$X$1,M8,$X$1,$V$1,$Y$1,$S$2,$U$1,$X$1,O8,$X$1,$V$1,$Y$1,Q8,$V$1,$Z$1) -> INSERT INTO "NationalTeams" (team_name,team_type,team_region_id,team_flag,team_shield,ol_country_id) VALUES ('Andorra','M',4,pg_read_binary_file('E:\imagenes\banderas\andorra.jpg'),pg_read_binary_file('E:\imagenes\escudos\andorra.png'),1);
B9: 7 | C9: Angola | E9: M | G9: 64 | H9: 61 | I9: 62 | J9: Africa | K9: =INDEX(TeamRegion!B:B,MATCH(J9,TeamRegion!C:C,0)) -> 1 | L9: \banderas\angola.jpg | M9: =_xlfn.CONCAT($I$2,L9) -> E:\imagenes\banderas\angola.jpg | N9: \escudos\angola.png | O9: =_xlfn.CONCAT($I$2,N9) -> E:\imagenes\escudos\angola.png | P9: Silnik | Q9: =INDEX(PlayerCountry!B:B,MATCH(P9,PlayerCountry!C:C,0)) -> 8 | S9: =_xlfn.CONCAT($S$1,$W$1,$B$1,$W$1," ",$U$1,$C$2,$Y$1,$E$2,$Y$1,$K$2,$Y$1,$M$2,$Y$1,$O$2,$Y$1,$Q$2,$V$1,$T$1,$U$1,$X$1,C9,$X$1,$Y$1,$X$1,E9,$X$1,$Y$1,K9,$Y$1,$S$2,$U$1,$X$1,M9,$X$1,$V$1,$Y$1,$S$2,$U$1,$X$1,O9,$X$1,$V$1,$Y$1,Q9,$V$1,$Z$1) -> INSERT INTO "NationalTeams" (team_name,team_type,team_region_id,team_flag,team_shield,ol_country_id) VALUES ('Angola','M',1,pg_read_binary_file('E:\imagenes\banderas\angola.jpg'),pg_read_binary_file('E:\imagenes\escudos\angola.png'),8);
B10: 8 | C10: Anguila | E10: M | G10: 46 | H10: 47 | I10: 46 | J10: America | K10: =INDEX(TeamRegion!B:B,MATCH(J10,TeamRegion!C:C,0)) -> 3 | L10: \banderas\anguila.png | M10: =_xlfn.CONCAT($I$2,L10) -> E:\imagenes\banderas\anguila.png | N10: \escudos\anguila.png | O10: =_xlfn.CONCAT($I$2,N10) -> E:\imagenes\escudos\anguila.png | P10: Pokemonia | Q10: =INDEX(PlayerCountry!B:B,MATCH(P10,PlayerCountry!C:C,0)) -> 5 | S10: =_xlfn.CONCAT($S$1,$W$1,$B$1,$W$1," ",$U$1,$C$2,$Y$1,$E$2,$Y$1,$K$2,$Y$1,$M$2,$Y$1,$O$2,$Y$1,$Q$2,$V$1,$T$1,$U$1,$X$1,C10,$X$1,$Y$1,$X$1,E10,$X$1,$Y$1,K10,$Y$1,$S$2,$U$1,$X$1,M10,$X$1,$V$1,$Y$1,$S$2,$U$1,$X$1,O10,$X$1,$V$1,$Y$1,Q10,$V$1,$Z$1) -> INSERT INTO "NationalTeams" (team_name,team_type,team_region_id,team_flag,team_shield,ol_country_id) VALUES ('Anguila','M',3,pg_read_binary_file('E:\imagenes\banderas\anguila.png'),pg_read_binary_file('E:\imagenes\escudos\anguila.png'),5);
B11: 9 | C11: Antigua y Barbuda | E11: M | G11: 58 | H11: 58 | I11: 59 | J11: America | K11: =INDEX(TeamRegion!B:B,MATCH(J11,TeamRegion!C:C,0)) -> 3 | L11: \banderas\antigua.png | M11: =_xlfn.CONCAT($I$2,L11) -> E:\imagenes\banderas\antigua.png | N11: \escudos\antigua.png | O11: =_xlfn.CONCAT($I$2,N11) -> E:\imagenes\escudos\antigua.png | P11: Igra | Q11: =INDEX(PlayerCountry!B:B,MATCH(P11,PlayerCountry!C:C,0)) -> 3 | S11: =_xlfn.CONCAT($S$1,$W$1,$B$1,$W$1," ",$U$1,$C$2,$Y$1,$E$2,$Y$1,$K$2,$Y$1,$M$2,$Y$1,$O$2,$Y$1,$Q$2,$V$1,$T$1,$U$1,$X$1,C11,$X$1,$Y$1,$X$1,E11,$X$1,$Y$1,K11,$Y$1,$S$2,$U$1,$X$1,M11,$X$1,$V$1,$Y$1,$S$2,$U$1,$X$1,O11,$X$1,$V$1,$Y$1,Q11,$V$1,$Z$1) -> INSERT INTO "NationalTeams" (team_name,team_type,team_region_id,team_flag,team_shield,ol_country_id) VALUES ('Antigua y Barbuda','M',3,pg_read_binary_file('E:\imagenes\banderas\antigua.png'),pg_read_binary_file('E:\imagenes\escudos\antigua.png'),3);
B12: 10 | C12: Arabia Saudita | E12: M | G12: 67 | H12: 68 | I12: 72 | J12: Asia | K12: =INDEX(TeamRegion!B:B,MATCH(J12,TeamRegion!C:C,0)) -> 2 | L12: \banderas\arabia saudita.jpg | M12: =_xlfn.CONCAT($I$2,L12) -> E:\imagenes\banderas\arabia saudita.jpg | N12: \escudos\arabia saudita.png | O12: =_xlfn.CONCAT($I$2,N12) -> E:\imagenes\escudos\arabia saudita.png | P12: Raimei | Q12: =INDEX(PlayerCountry!B:B,MATCH(P12,PlayerCountry!C:C,0)) -> 6 | S12: =_xlfn.CONCAT($S$1,$W$1,$B$1,$W$1," ",$U$1,$C$2,$Y$1,$E$2,$Y$1,$K$2,$Y$1,$M$2,$Y$1,$O$2,$Y$1,$Q$2,$V$1,$T$1,$U$1,$X$1,C12,$X$1,$Y$1,$X$1,E12,$X$1,$Y$1,K12,$Y$1,$S$2,$U$1,$X$1,M12,$X$1,$V$1,$Y$1,$S$2,$U$1,$X$1,O12,$X$1,$V$1,$Y$1,Q12,$V$1,$Z$1) -> INSERT INTO "NationalTeams" (team_name,team_type,team_region_id,team_flag,team_shield,ol_country_id) VALUES ('Arabia Saudita','M',2,pg_read_binary_file('E:\imagenes\banderas\arabia saudita.jpg'),pg_read_binary_file('E:\imagenes\escudos\arabia saudita.png'),6);
B13: 11 | C13: Argelia | E13: M | G13: 73 | H13: 75 | I13: 82 | J13: Africa | K13: =INDEX(TeamRegion!B:B,MATCH(J13,TeamRegion!C:C,0)) -> 1 | L13: \banderas\argelia.jpg | M13: =_xlfn.CONCAT($I$2,L13) -> E:\imagenes\banderas\argelia.jpg | N13: \escudos\argelia.png | O13: =_xlfn.CONCAT($I$2,N13) -> E:\imagenes\escudos\argelia.png | P13: Dinazor | Q13: =INDEX(PlayerCountry!B:B,MATCH(P13,PlayerCountry!C:C,0)) -> 2 | S13: =_xlfn.CONCAT($S$1,$W$1,$B$1,$W$1," ",$U$1,$C$2,$Y$1,$E$2,$Y$1,$K$2,$Y$1,$M$2,$Y$1,$O$2,$Y$1,$Q$2,$V$1,$T$1,$U$1,$X$1,C13,$X$1,$Y$1,$X$1,E13,$X$1,$Y$1,K13,$Y$1,$S$2,$U$1,$X$1,M13,$X$1,$V$1,$Y$1,$S$2,$U$1,$X$1,O13,$X$1,$V$1,$Y$1,Q13,$V$1,$Z$1) -> INSERT INTO "NationalTeams" (team_name,team_type,team_region_id,team_flag,team_shield,ol_country_id) VALUES ('Argelia','M',1,pg_read_binary_file('E:\imagenes\banderas\argelia.jpg'),pg_read_binary_file('E:\imagenes\escudos\argelia.png'),2);
B14: 12 | C14: Argentina | E14: M | G14: 81 | H14: 83 | I14: 91 | J14: America | K14: =INDEX(TeamRegion!B:B,MATCH(J14,TeamRegion!C:C,0)) -> 3 | L14: \banderas\argentina.jpg | M14: =_xlfn.CONCAT($I$2,L14) -> E:\imagenes\banderas\argentina.jpg | N14: \escudos\argentina.png | O14: =_xlfn.CONCAT($I$2,N14) -> E:\imagenes\escudos\argentina.png | P14: Bollstam | Q14: =INDEX(PlayerCountry!B:B,MATCH(P14,PlayerCountry!C:C,0)) -> 1 | S14: =_xlfn.CONCAT($S$1,$W$1,$B$1,$W$1," ",$U$1,$C$2,$Y$1,$E$2,$Y$1,$K$2,$Y$1,$M$2,$Y$1,$O$2,$Y$1,$Q$2,$V$1,$T$1,$U$1,$X$1,C14,$X$1,$Y$1,$X$1,E14,$X$1,$Y$1,K14,$Y$1,$S$2,$U$1,$X$1,M14,$X$1,$V$1,$Y$1,$S$2,$U$1,$X$1,O14,$X$1,$V$1,$Y$1,Q14,$V$1,$Z$1) -> INSERT INTO "NationalTeams" (team_name,team_type,team_region_id,team_flag,team_shield,ol_country_id) VALUES ('Argentina','M',3,pg_read_binary_file('E:\imagenes\banderas\argentina.jpg'),pg_read_binary_file('E:\imagenes\escudos\argentina.png'),1);
... B448: 446 | C448: Zimbaue Fem | E448: F | G448: 49 | H448: 49 | I448: 49 | J448: Africa | K448: =INDEX(TeamRegion!B:B,MATCH(J448,TeamRegion!C:C,0)) -> 1 | L448: \banderas\zimbaue.jpg | M448: =_xlfn.CONCAT($I$2,L448) -> E:\imagenes\banderas\zimbaue.jpg | N448: \escudos\zimbaue.png | O448: =_xlfn.CONCAT($I$2,N448) -> E:\imagenes\escudos\zimbaue.png | P448: Lordena | Q448: =INDEX(PlayerCountry!B:B,MATCH(P448,PlayerCountry!C:C,0)) -> 4 | S448: =_xlfn.CONCAT($S$1,$W$1,$B$1,$W$1," ",$U$1,$C$2,$Y$1,$E$2,$Y$1,$K$2,$Y$1,$M$2,$Y$1,$O$2,$Y$1,$Q$2,$V$1,$T$1,$U$1,$X$1,C448,$X$1,$Y$1,$X$1,E448,$X$1,$Y$1,K448,$Y$1,$S$2,$U$1,$X$1,M448,$X$1,$V$1,$Y$1,$S$2,$U$1,$X$1,O448,$X$1,$V$1,$Y$1,Q448,$V$1,$Z$1) -> INSERT INTO "NationalTeams" (team_name,team_type,team_region_id,team_flag,team_shield,ol_country_id) VALUES ('Zimbaue Fem','F',1,pg_read_binary_file('E:\imagenes\banderas\zimbaue.jpg'),pg_read_binary_file('E:\imagenes\escudos\zimbaue.png'),4);

Sheet OlympicPlayers
A1: E:\imagenes | B1: OlympicPlayers | L1: INSERT INTO | M1: VALUES | N1: ( | O1: ) | P1: " | Q1: ' | R1: , | S1: ;
B2: ol_player_id | C2: ol_player_name | D2: ol_player_value | E2: ruta | F2: ol_player_image | G2: country | H2: ol_country_id | I2: sport | J2: team_sport_id | L2: pg_read_binary_file
B3: 1 | C3: Jim Rivers | D3: 1 | E3: \personajes\jim_rivers.png | F3: =_xlfn.CONCAT($A$1,E3) -> E:\imagenes\personajes\jim_rivers.png | G3: Lordena | H3: =INDEX(PlayerCountry!B:B,MATCH(G3,PlayerCountry!C:C,0)) -> 4 | I3: Excitebike | J3: =INDEX(TeamSports!B:B,MATCH(I3,TeamSports!C:C,0)) -> 40 | L3: =_xlfn.CONCAT($L$1,$P$1,$B$1,$P$1," ",$N$1,$C$2,$R$1,$D$2,$R$1,$F$2,$R$1,$H$2,$R$1,$J$2,$O$1,$M$1,$N$1,$Q$1,C3,$Q$1,$R$1,D3,$R$1,$L$2,$N$1,$Q$1,F3,$Q$1,$O$1,$R$1,H3,$R$1,J3,$O$1,$S$1) -> INSERT INTO "OlympicPlayers" (ol_player_name,ol_player_value,ol_player_image,ol_country_id,team_sport_id) VALUES ('Jim Rivers',1,pg_read_binary_file('E:\imagenes\personajes\jim_rivers.png'),4,40);
B4: 2 | C4: Sarah Hill | D4: 1 | E4: \personajes\sarah_hill.png | F4: =_xlfn.CONCAT($A$1,E4) -> E:\imagenes\personajes\sarah_hill.png | G4: Bollstam | H4: =INDEX(PlayerCountry!B:B,MATCH(G4,PlayerCountry!C:C,0)) -> 1 | I4: Excitebike | J4: =INDEX(TeamSports!B:B,MATCH(I4,TeamSports!C:C,0)) -> 40 | L4: =_xlfn.CONCAT($L$1,$P$1,$B$1,$P$1," ",$N$1,$C$2,$R$1,$D$2,$R$1,$F$2,$R$1,$H$2,$R$1,$J$2,$O$1,$M$1,$N$1,$Q$1,C4,$Q$1,$R$1,D4,$R$1,$L$2,$N$1,$Q$1,F4,$Q$1,$O$1,$R$1,H4,$R$1,J4,$O$1,$S$1) -> INSERT INTO "OlympicPlayers" (ol_player_name,ol_player_value,ol_player_image,ol_country_id,team_sport_id) VALUES ('Sarah Hill',1,pg_read_binary_file('E:\imagenes\personajes\sarah_hill.png'),1,40);
B5: 3 | C5: Bobby Malone | D5: 1 | E5: \personajes\bobby_malone.png | F5: =_xlfn.CONCAT($A$1,E5) -> E:\imagenes\personajes\bobby_malone.png | G5: Dinazor | H5: =INDEX(PlayerCountry!B:B,MATCH(G5,PlayerCountry!C:C,0)) -> 2 | I5: Excitebike | J5: =INDEX(TeamSports!B:B,MATCH(I5,TeamSports!C:C,0)) -> 40 | L5: =_xlfn.CONCAT($L$1,$P$1,$B$1,$P$1," ",$N$1,$C$2,$R$1,$D$2,$R$1,$F$2,$R$1,$H$2,$R$1,$J$2,$O$1,$M$1,$N$1,$Q$1,C5,$Q$1,$R$1,D5,$R$1,$L$2,$N$1,$Q$1,F5,$Q$1,$O$1,$R$1,H5,$R$1,J5,$O$1,$S$1) -> INSERT INTO "OlympicPlayers" (ol_player_name,ol_player_value,ol_player_image,ol_country_id,team_sport_id) VALUES ('Bobby Malone',1,pg_read_binary_file('E:\imagenes\personajes\bobby_malone.png'),2,40);
B6: 4 | C6: Vicky Steele | D6: 1 | E6: \personajes\vicky_steele.png | F6: =_xlfn.CONCAT($A$1,E6) -> E:\imagenes\personajes\vicky_steele.png | G6: Schattenmond | H6: =INDEX(PlayerCountry!B:B,MATCH(G6,PlayerCountry!C:C,0)) -> 7 | I6: Excitebike | J6: =INDEX(TeamSports!B:B,MATCH(I6,TeamSports!C:C,0)) -> 40 | L6: =_xlfn.CONCAT($L$1,$P$1,$B$1,$P$1," ",$N$1,$C$2,$R$1,$D$2,$R$1,$F$2,$R$1,$H$2,$R$1,$J$2,$O$1,$M$1,$N$1,$Q$1,C6,$Q$1,$R$1,D6,$R$1,$L$2,$N$1,$Q$1,F6,$Q$1,$O$1,$R$1,H6,$R$1,J6,$O$1,$S$1) -> INSERT INTO "OlympicPlayers" (ol_player_name,ol_player_value,ol_player_image,ol_country_id,team_sport_id) VALUES ('Vicky Steele',1,pg_read_binary_file('E:\imagenes\personajes\vicky_steele.png'),7,40);
B7: 5 | C7: Ricky Stern | D7: 1 | E7: \personajes\ricky_stern.png | F7: =_xlfn.CONCAT($A$1,E7) -> E:\imagenes\personajes\ricky_stern.png | G7: Dinazor | H7: =INDEX(PlayerCountry!B:B,MATCH(G7,PlayerCountry!C:C,0)) -> 2 | I7: Excitebike | J7: =INDEX(TeamSports!B:B,MATCH(I7,TeamSports!C:C,0)) -> 40 | L7: =_xlfn.CONCAT($L$1,$P$1,$B$1,$P$1," ",$N$1,$C$2,$R$1,$D$2,$R$1,$F$2,$R$1,$H$2,$R$1,$J$2,$O$1,$M$1,$N$1,$Q$1,C7,$Q$1,$R$1,D7,$R$1,$L$2,$N$1,$Q$1,F7,$Q$1,$O$1,$R$1,H7,$R$1,J7,$O$1,$S$1) -> INSERT INTO "OlympicPlayers" (ol_player_name,ol_player_value,ol_player_image,ol_country_id,team_sport_id) VALUES ('Ricky Stern',1,pg_read_binary_file('E:\imagenes\personajes\ricky_stern.png'),2,40);
B8: 6 | C8: Nigel York | D8: 1 | E8: \personajes\nigel_york.png | F8: =_xlfn.CONCAT($A$1,E8) -> E:\imagenes\personajes\nigel_york.png | G8: Silnik | H8: =INDEX(PlayerCountry!B:B,MATCH(G8,PlayerCountry!C:C,0)) -> 8 | I8: Excitebike | J8: =INDEX(TeamSports!B:B,MATCH(I8,TeamSports!C:C,0)) -> 40 | L8: =_xlfn.CONCAT($L$1,$P$1,$B$1,$P$1," ",$N$1,$C$2,$R$1,$D$2,$R$1,$F$2,$R$1,$H$2,$R$1,$J$2,$O$1,$M$1,$N$1,$Q$1,C8,$Q$1,$R$1,D8,$R$1,$L$2,$N$1,$Q$1,F8,$Q$1,$O$1,$R$1,H8,$R$1,J8,$O$1,$S$1) -> INSERT INTO "OlympicPlayers" (ol_player_name,ol_player_value,ol_player_image,ol_country_id,team_sport_id) VALUES ('Nigel York',1,pg_read_binary_file('E:\imagenes\personajes\nigel_york.png'),8,40);
B9: 7 | C9: Juan Pablo Montoya | D9: 1 | E9: =_xlfn.CONCAT("\personajes\",SUBSTITUTE(LOWER(C9)," ","_"),".png") -> \personajes\juan_pablo_montoya.png | F9: =_xlfn.CONCAT($A$1,E9) -> E:\imagenes\personajes\juan_pablo_montoya.png | G9: Bollstam | H9: =INDEX(PlayerCountry!B:B,MATCH(G9,PlayerCountry!C:C,0)) -> 1 | I9: Formula1 | J9: =INDEX(TeamSports!B:B,MATCH(I9,TeamSports!C:C,0)) -> 41 | L9: =_xlfn.CONCAT($L$1,$P$1,$B$1,$P$1," ",$N$1,$C$2,$R$1,$D$2,$R$1,$F$2,$R$1,$H$2,$R$1,$J$2,$O$1,$M$1,$N$1,$Q$1,C9,$Q$1,$R$1,D9,$R$1,$L$2,$N$1,$Q$1,F9,$Q$1,$O$1,$R$1,H9,$R$1,J9,$O$1,$S$1) -> INSERT INTO "OlympicPlayers" (ol_player_name,ol_player_value,ol_player_image,ol_country_id,team_sport_id) VALUES ('Juan Pablo Montoya',1,pg_read_binary_file('E:\imagenes\personajes\juan_pablo_montoya.png'),1,41);
B10: 8 | C10: Heinz Harald Frentzen | D10: 1 | E10: =_xlfn.CONCAT("\personajes\",SUBSTITUTE(LOWER(C10)," ","_"),".png") -> \personajes\heinz_harald_frentzen.png | F10: =_xlfn.CONCAT($A$1,E10) -> E:\imagenes\personajes\heinz_harald_frentzen.png | G10: Dinazor | H10: =INDEX(PlayerCountry!B:B,MATCH(G10,PlayerCountry!C:C,0)) -> 2 | I10: Formula1 | J10: =INDEX(TeamSports!B:B,MATCH(I10,TeamSports!C:C,0)) -> 41 | L10: =_xlfn.CONCAT($L$1,$P$1,$B$1,$P$1," ",$N$1,$C$2,$R$1,$D$2,$R$1,$F$2,$R$1,$H$2,$R$1,$J$2,$O$1,$M$1,$N$1,$Q$1,C10,$Q$1,$R$1,D10,$R$1,$L$2,$N$1,$Q$1,F10,$Q$1,$O$1,$R$1,H10,$R$1,J10,$O$1,$S$1) -> INSERT INTO "OlympicPlayers" (ol_player_name,ol_player_value,ol_player_image,ol_country_id,team_sport_id) VALUES ('Heinz Harald Frentzen',1,pg_read_binary_file('E:\imagenes\personajes\heinz_harald_frentzen.png'),2,41);
B11: 9 | C11: Michael Schuhmacher | D11: 1 | E11: =_xlfn.CONCAT("\personajes\",SUBSTITUTE(LOWER(C11)," ","_"),".png") -> \personajes\michael_schuhmacher.png | F11: =_xlfn.CONCAT($A$1,E11) -> E:\imagenes\personajes\michael_schuhmacher.png | G11: Dinazor | H11: =INDEX(PlayerCountry!B:B,MATCH(G11,PlayerCountry!C:C,0)) -> 2 | I11: Formula1 | J11: =INDEX(TeamSports!B:B,MATCH(I11,TeamSports!C:C,0)) -> 41 | L11: =_xlfn.CONCAT($L$1,$P$1,$B$1,$P$1," ",$N$1,$C$2,$R$1,$D$2,$R$1,$F$2,$R$1,$H$2,$R$1,$J$2,$O$1,$M$1,$N$1,$Q$1,C11,$Q$1,$R$1,D11,$R$1,$L$2,$N$1,$Q$1,F11,$Q$1,$O$1,$R$1,H11,$R$1,J11,$O$1,$S$1) -> INSERT INTO "OlympicPlayers" (ol_player_name,ol_player_value,ol_player_image,ol_country_id,team_sport_id) VALUES ('Michael Schuhmacher',1,pg_read_binary_file('E:\imagenes\personajes\michael_schuhmacher.png'),2,41);
B12: 10 | C12: Gerhard Berger | D12: 1 | E12: =_xlfn.CONCAT("\personajes\",SUBSTITUTE(LOWER(C12)," ","_"),".png") -> \personajes\gerhard_berger.png | F12: =_xlfn.CONCAT($A$1,E12) -> E:\imagenes\personajes\gerhard_berger.png | G12: Igra | H12: =INDEX(PlayerCountry!B:B,MATCH(G12,PlayerCountry!C:C,0)) -> 3 | I12: Formula1 | J12: =INDEX(TeamSports!B:B,MATCH(I12,TeamSports!C:C,0)) -> 41 | L12: =_xlfn.CONCAT($L$1,$P$1,$B$1,$P$1," ",$N$1,$C$2,$R$1,$D$2,$R$1,$F$2,$R$1,$H$2,$R$1,$J$2,$O$1,$M$1,$N$1,$Q$1,C12,$Q$1,$R$1,D12,$R$1,$L$2,$N$1,$Q$1,F12,$Q$1,$O$1,$R$1,H12,$R$1,J12,$O$1,$S$1) -> INSERT INTO "OlympicPlayers" (ol_player_name,ol_player_value,ol_player_image,ol_country_id,team_sport_id) VALUES ('Gerhard Berger',1,pg_read_binary_file('E:\imagenes\personajes\gerhard_berger.png'),3,41);
B13: 11 | C13: Ralph Schuhmacher | D13: 1 | E13: =_xlfn.CONCAT("\personajes\",SUBSTITUTE(LOWER(C13)," ","_"),".png") -> \personajes\ralph_schuhmacher.png | F13: =_xlfn.CONCAT($A$1,E13) -> E:\imagenes\personajes\ralph_schuhmacher.png | G13: Dinazor | H13: =INDEX(PlayerCountry!B:B,MATCH(G13,PlayerCountry!C:C,0)) -> 2 | I13: Formula1 | J13: =INDEX(TeamSports!B:B,MATCH(I13,TeamSports!C:C,0)) -> 41 | L13: =_xlfn.CONCAT($L$1,$P$1,$B$1,$P$1," ",$N$1,$C$2,$R$1,$D$2,$R$1,$F$2,$R$1,$H$2,$R$1,$J$2,$O$1,$M$1,$N$1,$Q$1,C13,$Q$1,$R$1,D13,$R$1,$L$2,$N$1,$Q$1,F13,$Q$1,$O$1,$R$1,H13,$R$1,J13,$O$1,$S$1) -> INSERT INTO "OlympicPlayers" (ol_player_name,ol_player_value,ol_player_image,ol_country_id,team_sport_id) VALUES ('Ralph Schuhmacher',1,pg_read_binary_file('E:\imagenes\personajes\ralph_schuhmacher.png'),2,41);
B14: 12 | C14: Jean Alesi | D14: 1 | E14: =_xlfn.CONCAT("\personajes\",SUBSTITUTE(LOWER(C14)," ","_"),".png") -> \personajes\jean_alesi.png | F14: =_xlfn.CONCAT($A$1,E14) -> E:\imagenes\personajes\jean_alesi.png | G14: Lordena | H14: =INDEX(PlayerCountry!B:B,MATCH(G14,PlayerCountry!C:C,0)) -> 4 | I14: Formula1 | J14: =INDEX(TeamSports!B:B,MATCH(I14,TeamSports!C:C,0)) -> 41 | L14: =_xlfn.CONCAT($L$1,$P$1,$B$1,$P$1," ",$N$1,$C$2,$R$1,$D$2,$R$1,$F$2,$R$1,$H$2,$R$1,$J$2,$O$1,$M$1,$N$1,$Q$1,C14,$Q$1,$R$1,D14,$R$1,$L$2,$N$1,$Q$1,F14,$Q$1,$O$1,$R$1,H14,$R$1,J14,$O$1,$S$1) -> INSERT INTO "OlympicPlayers" (ol_player_name,ol_player_value,ol_player_image,ol_country_id,team_sport_id) VALUES ('Jean Alesi',1,pg_read_binary_file('E:\imagenes\personajes\jean_alesi.png'),4,41);
B15: 13 | C15: Mika Hakkinen | D15: 1 | E15: =_xlfn.CONCAT("\personajes\",SUBSTITUTE(LOWER(C15)," ","_"),".png") -> \personajes\mika_hakkinen.png | F15: =_xlfn.CONCAT($A$1,E15) -> E:\imagenes\personajes\mika_hakkinen.png | G15: Bollstam | H15: =INDEX(PlayerCountry!B:B,MATCH(G15,PlayerCountry!C:C,0)) -> 1 | I15: Formula1 | J15: =INDEX(TeamSports!B:B,MATCH(I15,TeamSports!C:C,0)) -> 41 | L15: =_xlfn.CONCAT($L$1,$P$1,$B$1,$P$1," ",$N$1,$C$2,$R$1,$D$2,$R$1,$F$2,$R$1,$H$2,$R$1,$J$2,$O$1,$M$1,$N$1,$Q$1,C15,$Q$1,$R$1,D15,$R$1,$L$2,$N$1,$Q$1,F15,$Q$1,$O$1,$R$1,H15,$R$1,J15,$O$1,$S$1) -> INSERT INTO "OlympicPlayers" (ol_player_name,ol_player_value,ol_player_image,ol_country_id,team_sport_id) VALUES ('Mika Hakkinen',1,pg_read_binary_file('E:\imagenes\personajes\mika_hakkinen.png'),1,41);
B16: 14 | C16: Damon Hill | D16: 1 | E16: =_xlfn.CONCAT("\personajes\",SUBSTITUTE(LOWER(C16)," ","_"),".png") -> \personajes\damon_hill.png | F16: =_xlfn.CONCAT($A$1,E16) -> E:\imagenes\personajes\damon_hill.png | G16: Lordena | H16: =INDEX(PlayerCountry!B:B,MATCH(G16,PlayerCountry!C:C,0)) -> 4 | I16: Formula1 | J16: =INDEX(TeamSports!B:B,MATCH(I16,TeamSports!C:C,0)) -> 41 | L16: =_xlfn.CONCAT($L$1,$P$1,$B$1,$P$1," ",$N$1,$C$2,$R$1,$D$2,$R$1,$F$2,$R$1,$H$2,$R$1,$J$2,$O$1,$M$1,$N$1,$Q$1,C16,$Q$1,$R$1,D16,$R$1,$L$2,$N$1,$Q$1,F16,$Q$1,$O$1,$R$1,H16,$R$1,J16,$O$1,$S$1) -> INSERT INTO "OlympicPlayers" (ol_player_name,ol_player_value,ol_player_image,ol_country_id,team_sport_id) VALUES ('Damon Hill',1,pg_read_binary_file('E:\imagenes\personajes\damon_hill.png'),4,41);
B17: 15 | C17: David Coulthard | D17: 1 | E17: =_xlfn.CONCAT("\personajes\",SUBSTITUTE(LOWER(C17)," ","_"),".png") -> \personajes\david_coulthard.png | F17: =_xlfn.CONCAT($A$1,E17) -> E:\imagenes\personajes\david_coulthard.png | G17: Lordena | H17: =INDEX(PlayerCountry!B:B,MATCH(G17,PlayerCountry!C:C,0)) -> 4 | I17: Formula1 | J17: =INDEX(TeamSports!B:B,MATCH(I17,TeamSports!C:C,0)) -> 41 | L17: =_xlfn.CONCAT($L$1,$P$1,$B$1,$P$1," ",$N$1,$C$2,$R$1,$D$2,$R$1,$F$2,$R$1,$H$2,$R$1,$J$2,$O$1,$M$1,$N$1,$Q$1,C17,$Q$1,$R$1,D17,$R$1,$L$2,$N$1,$Q$1,F17,$Q$1,$O$1,$R$1,H17,$R$1,J17,$O$1,$S$1) -> INSERT INTO "OlympicPlayers" (ol_player_name,ol_player_value,ol_player_image,ol_country_id,team_sport_id) VALUES ('David Coulthard',1,pg_read_binary_file('E:\imagenes\personajes\david_coulthard.png'),4,41);
B18: 16 | C18: Pedro Diniz | D18: 1 | E18: =_xlfn.CONCAT("\personajes\",SUBSTITUTE(LOWER(C18)," ","_"),".png") -> \personajes\pedro_diniz.png | F18: =_xlfn.CONCAT($A$1,E18) -> E:\imagenes\personajes\pedro_diniz.png | G18: Dinazor | H18: =INDEX(PlayerCountry!B:B,MATCH(G18,PlayerCountry!C:C,0)) -> 2 | I18: Formula1 | J18: =INDEX(TeamSports!B:B,MATCH(I18,TeamSports!C:C,0)) -> 41 | L18: =_xlfn.CONCAT($L$1,$P$1,$B$1,$P$1," ",$N$1,$C$2,$R$1,$D$2,$R$1,$F$2,$R$1,$H$2,$R$1,$J$2,$O$1,$M$1,$N$1,$Q$1,C18,$Q$1,$R$1,D18,$R$1,$L$2,$N$1,$Q$1,F18,$Q$1,$O$1,$R$1,H18,$R$1,J18,$O$1,$S$1) -> INSERT INTO "OlympicPlayers" (ol_player_name,ol_player_value,ol_player_image,ol_country_id,team_sport_id) VALUES ('Pedro Diniz',1,pg_read_binary_file('E:\imagenes\personajes\pedro_diniz.png'),2,41);
B19: 17 | C19: Giancarlo Fisichella | D19: 1 | E19: =_xlfn.CONCAT("\personajes\",SUBSTITUTE(LOWER(C19)," ","_"),".png") -> \personajes\giancarlo_fisichella.png | F19: =_xlfn.CONCAT($A$1,E19) -> E:\imagenes\personajes\giancarlo_fisichella.png | G19: Dinazor | H19: =INDEX(PlayerCountry!B:B,MATCH(G19,PlayerCountry!C:C,0)) -> 2 | I19: Formula1 | J19: =INDEX(TeamSports!B:B,MATCH(I19,TeamSports!C:C,0)) -> 41 | L19: =_xlfn.CONCAT($L$1,$P$1,$B$1,$P$1," ",$N$1,$C$2,$R$1,$D$2,$R$1,$F$2,$R$1,$H$2,$R$1,$J$2,$O$1,$M$1,$N$1,$Q$1,C19,$Q$1,$R$1,D19,$R$1,$L$2,$N$1,$Q$1,F19,$Q$1,$O$1,$R$1,H19,$R$1,J19,$O$1,$S$1) -> INSERT INTO "OlympicPlayers" (ol_player_name,ol_player_value,ol_player_image,ol_country_id,team_sport_id) VALUES ('Giancarlo Fisichella',1,pg_read_binary_file('E:\imagenes\personajes\giancarlo_fisichella.png'),2,41);
B20: 18 | C20: Eddie Irvine | D20: 1 | E20: =_xlfn.CONCAT("\personajes\",SUBSTITUTE(LOWER(C20)," ","_"),".png") -> \personajes\eddie_irvine.png | F20: =_xlfn.CONCAT($A$1,E20) -> E:\imagenes\personajes\eddie_irvine.png | G20: Lordena | H20: =INDEX(PlayerCountry!B:B,MATCH(G20,PlayerCountry!C:C,0)) -> 4 | I20: Formula1 | J20: =INDEX(TeamSports!B:B,MATCH(I20,TeamSports!C:C,0)) -> 41 | L20: =_xlfn.CONCAT($L$1,$P$1,$B$1,$P$1," ",$N$1,$C$2,$R$1,$D$2,$R$1,$F$2,$R$1,$H$2,$R$1,$J$2,$O$1,$M$1,$N$1,$Q$1,C20,$Q$1,$R$1,D20,$R$1,$L$2,$N$1,$Q$1,F20,$Q$1,$O$1,$R$1,H20,$R$1,J20,$O$1,$S$1) -> INSERT INTO "OlympicPlayers" (ol_player_name,ol_player_value,ol_player_image,ol_country_id,team_sport_id) VALUES ('Eddie Irvine',1,pg_read_binary_file('E:\imagenes\personajes\eddie_irvine.png'),4,41);
... B60: 58 | C60: Zoda | D60: 1 | E60: =_xlfn.CONCAT("\personajes\",SUBSTITUTE(LOWER(C60)," ","_"),".png") -> \personajes\zoda.png | F60: =_xlfn.CONCAT($A$1,E60) -> E:\imagenes\personajes\zoda.png | G60: Dinazor | H60: =INDEX(PlayerCountry!B:B,MATCH(G60,PlayerCountry!C:C,0)) -> 2 | I60: F-Zero | J60: =INDEX(TeamSports!B:B,MATCH(I60,TeamSports!C:C,0)) -> 42 | L60: =_xlfn.CONCAT($L$1,$P$1,$B$1,$P$1," ",$N$1,$C$2,$R$1,$D$2,$R$1,$F$2,$R$1,$H$2,$R$1,$J$2,$O$1,$M$1,$N$1,$Q$1,C60,$Q$1,$R$1,D60,$R$1,$L$2,$N$1,$Q$1,F60,$Q$1,$O$1,$R$1,H60,$R$1,J60,$O$1,$S$1) -> INSERT INTO "OlympicPlayers" (ol_player_name,ol_player_value,ol_player_image,ol_country_id,team_sport_id) VALUES ('Zoda',1,pg_read_binary_file('E:\imagenes\personajes\zoda.png'),2,42);
B61: 59 | C61: Dimitri Mishkin | D61: 1 | E61: \personajes\mishkin.png | F61: =_xlfn.CONCAT($A$1,E61) -> E:\imagenes\personajes\mishkin.png | G61: Dinazor | H61: =INDEX(PlayerCountry!B:B,MATCH(G61,PlayerCountry!C:C,0)) -> 2 | I61: Goldeneye | J61: =INDEX(TeamSports!B:B,MATCH(I61,TeamSports!C:C,0)) -> 43 | L61: =_xlfn.CONCAT($L$1,$P$1,$B$1,$P$1," ",$N$1,$C$2,$R$1,$D$2,$R$1,$F$2,$R$1,$H$2,$R$1,$J$2,$O$1,$M$1,$N$1,$Q$1,C61,$Q$1,$R$1,D61,$R$1,$L$2,$N$1,$Q$1,F61,$Q$1,$O$1,$R$1,H61,$R$1,J61,$O$1,$S$1) -> INSERT INTO "OlympicPlayers" (ol_player_name,ol_player_value,ol_player_image,ol_country_id,team_sport_id) VALUES ('Dimitri Mishkin',1,pg_read_binary_file('E:\imagenes\personajes\mishkin.png'),2,43);
B62: 60 | C62: Alan | D62: 1 | E62: \personajes\goldeneye.png | F62: =_xlfn.CONCAT($A$1,E62) -> E:\imagenes\personajes\goldeneye.png | G62: Lordena | H62: =INDEX(PlayerCountry!B:B,MATCH(G62,PlayerCountry!C:C,0)) -> 4 | I62: Goldeneye | J62: =INDEX(TeamSports!B:B,MATCH(I62,TeamSports!C:C,0)) -> 43 | L62: =_xlfn.CONCAT($L$1,$P$1,$B$1,$P$1," ",$N$1,$C$2,$R$1,$D$2,$R$1,$F$2,$R$1,$H$2,$R$1,$J$2,$O$1,$M$1,$N$1,$Q$1,C62,$Q$1,$R$1,D62,$R$1,$L$2,$N$1,$Q$1,F62,$Q$1,$O$1,$R$1,H62,$R$1,J62,$O$1,$S$1) -> INSERT INTO "OlympicPlayers" (ol_player_name,ol_player_value,ol_player_image,ol_country_id,team_sport_id) VALUES ('Alan',1,pg_read_binary_file('E:\imagenes\personajes\goldeneye.png'),4,43);
B63: 61 | C63: Xenia Onatopp | D63: 1 | E63: \personajes\xenia.png | F63: =_xlfn.CONCAT($A$1,E63) -> E:\imagenes\personajes\xenia.png | G63: Bollstam | H63: =INDEX(PlayerCountry!B:B,MATCH(G63,PlayerCountry!C:C,0)) -> 1 | I63: Goldeneye | J63: =INDEX(TeamSports!B:B,MATCH(I63,TeamSports!C:C,0)) -> 43 | L63: =_xlfn.CONCAT($L$1,$P$1,$B$1,$P$1," ",$N$1,$C$2,$R$1,$D$2,$R$1,$F$2,$R$1,$H$2,$R$1,$J$2,$O$1,$M$1,$N$1,$Q$1,C63,$Q$1,$R$1,D63,$R$1,$L$2,$N$1,$Q$1,F63,$Q$1,$O$1,$R$1,H63,$R$1,J63,$O$1,$S$1) -> INSERT INTO "OlympicPlayers" (ol_player_name,ol_player_value,ol_player_image,ol_country_id,team_sport_id) VALUES ('Xenia Onatopp',1,pg_read_binary_file('E:\imagenes\personajes\xenia.png'),1,43);
B64: 62 | C64: Arkady Ourumov | D64: 1 | E64: \personajes\ourumov.png | F64: =_xlfn.CONCAT($A$1,E64) -> E:\imagenes\personajes\ourumov.png | G64: Dinazor | H64: =INDEX(PlayerCountry!B:B,MATCH(G64,PlayerCountry!C:C,0)) -> 2 | I64: Goldeneye | J64: =INDEX(TeamSports!B:B,MATCH(I64,TeamSports!C:C,0)) -> 43 | L64: =_xlfn.CONCAT($L$1,$P$1,$B$1,$P$1," ",$N$1,$C$2,$R$1,$D$2,$R$1,$F$2,$R$1,$H$2,$R$1,$J$2,$O$1,$M$1,$N$1,$Q$1,C64,$Q$1,$R$1,D64,$R$1,$L$2,$N$1,$Q$1,F64,$Q$1,$O$1,$R$1,H64,$R$1,J64,$O$1,$S$1) -> INSERT INTO "OlympicPlayers" (ol_player_name,ol_player_value,ol_player_image,ol_country_id,team_sport_id) VALUES ('Arkady Ourumov',1,pg_read_binary_file('E:\imagenes\personajes\ourumov.png'),2,43);
B65: 63 | C65: James Bond | D65: 1 | E65: \personajes\bond.png | F65: =_xlfn.CONCAT($A$1,E65) -> E:\imagenes\personajes\bond.png | G65: Lordena | H65: =INDEX(PlayerCountry!B:B,MATCH(G65,PlayerCountry!C:C,0)) -> 4 | I65: Goldeneye | J65: =INDEX(TeamSports!B:B,MATCH(I65,TeamSports!C:C,0)) -> 43 | L65: =_xlfn.CONCAT($L$1,$P$1,$B$1,$P$1," ",$N$1,$C$2,$R$1,$D$2,$R$1,$F$2,$R$1,$H$2,$R$1,$J$2,$O$1,$M$1,$N$1,$Q$1,C65,$Q$1,$R$1,D65,$R$1,$L$2,$N$1,$Q$1,F65,$Q$1,$O$1,$R$1,H65,$R$1,J65,$O$1,$S$1) -> INSERT INTO "OlympicPlayers" (ol_player_name,ol_player_value,ol_player_image,ol_country_id,team_sport_id) VALUES ('James Bond',1,pg_read_binary_file('E:\imagenes\personajes\bond.png'),4,43);
B66: 64 | C66: Martin | D66: 1 | E66: \personajes\goldeneye.png | F66: =_xlfn.CONCAT($A$1,E66) -> E:\imagenes\personajes\goldeneye.png | G66: Pokemonia | H66: =INDEX(PlayerCountry!B:B,MATCH(G66,PlayerCountry!C:C,0)) -> 5 | I66: Goldeneye | J66: =INDEX(TeamSports!B:B,MATCH(I66,TeamSports!C:C,0)) -> 43 | L66: =_xlfn.CONCAT($L$1,$P$1,$B$1,$P$1," ",$N$1,$C$2,$R$1,$D$2,$R$1,$F$2,$R$1,$H$2,$R$1,$J$2,$O$1,$M$1,$N$1,$Q$1,C66,$Q$1,$R$1,D66,$R$1,$L$2,$N$1,$Q$1,F66,$Q$1,$O$1,$R$1,H66,$R$1,J66,$O$1,$S$1) -> INSERT INTO "OlympicPlayers" (ol_player_name,ol_player_value,ol_player_image,ol_country_id,team_sport_id) VALUES ('Martin',1,pg_read_binary_file('E:\imagenes\personajes\goldeneye.png'),5,43);
B67: 65 | C67: Rosika | D67: 1 | E67: \personajes\rosika.png | F67: =_xlfn.CONCAT($A$1,E67) -> E:\imagenes\personajes\rosika.png | G67: Bollstam | H67: =INDEX(PlayerCountry!B:B,MATCH(G67,PlayerCountry!C:C,0)) -> 1 | I67: Goldeneye | J67: =INDEX(TeamSports!B:B,MATCH(I67,TeamSports!C:C,0)) -> 43 | L67: =_xlfn.CONCAT($L$1,$P$1,$B$1,$P$1," ",$N$1,$C$2,$R$1,$D$2,$R$1,$F$2,$R$1,$H$2,$R$1,$J$2,$O$1,$M$1,$N$1,$Q$1,C67,$Q$1,$R$1,D67,$R$1,$L$2,$N$1,$Q$1,F67,$Q$1,$O$1,$R$1,H67,$R$1,J67,$O$1,$S$1) -> INSERT INTO "OlympicPlayers" (ol_player_name,ol_player_value,ol_player_image,ol_country_id,team_sport_id) VALUES ('Rosika',1,pg_read_binary_file('E:\imagenes\personajes\rosika.png'),1,43);
B68: 66 | C68: Baron Samedi | D68: 1 | E68: \personajes\samedi.png | F68: =_xlfn.CONCAT($A$1,E68) -> E:\imagenes\personajes\samedi.png | G68: Dinazor | H68: =INDEX(PlayerCountry!B:B,MATCH(G68,PlayerCountry!C:C,0)) -> 2 | I68: Goldeneye | J68: =INDEX(TeamSports!B:B,MATCH(I68,TeamSports!C:C,0)) -> 43 | L68: =_xlfn.CONCAT($L$1,$P$1,$B$1,$P$1," ",$N$1,$C$2,$R$1,$D$2,$R$1,$F$2,$R$1,$H$2,$R$1,$J$2,$O$1,$M$1,$N$1,$Q$1,C68,$Q$1,$R$1,D68,$R$1,$L$2,$N$1,$Q$1,F68,$Q$1,$O$1,$R$1,H68,$R$1,J68,$O$1,$S$1) -> INSERT INTO "OlympicPlayers" (ol_player_name,ol_player_value,ol_player_image,ol_country_id,team_sport_id) VALUES ('Baron Samedi',1,pg_read_binary_file('E:\imagenes\personajes\samedi.png'),2,43);
B69: 67 | C69: Mayday | D69: 1 | E69: \personajes\mayday.png | F69: =_xlfn.CONCAT($A$1,E69) -> E:\imagenes\personajes\mayday.png | G69: Igra | H69: =INDEX(PlayerCountry!B:B,MATCH(G69,PlayerCountry!C:C,0)) -> 3 | I69: Goldeneye | J69: =INDEX(TeamSports!B:B,MATCH(I69,TeamSports!C:C,0)) -> 43 | L69: =_xlfn.CONCAT($L$1,$P$1,$B$1,$P$1," ",$N$1,$C$2,$R$1,$D$2,$R$1,$F$2,$R$1,$H$2,$R$1,$J$2,$O$1,$M$1,$N$1,$Q$1,C69,$Q$1,$R$1,D69,$R$1,$L$2,$N$1,$Q$1,F69,$Q$1,$O$1,$R$1,H69,$R$1,J69,$O$1,$S$1) -> INSERT INTO "OlympicPlayers" (ol_player_name,ol_player_value,ol_player_image,ol_country_id,team_sport_id) VALUES ('Mayday',1,pg_read_binary_file('E:\imagenes\personajes\mayday.png'),3,43);
B70: 68 | C70: Lee | D70: 1 | E70: \personajes\goldeneye.png | F70: =_xlfn.CONCAT($A$1,E70) -> E:\imagenes\personajes\goldeneye.png | G70: Raimei | H70: =INDEX(PlayerCountry!B:B,MATCH(G70,PlayerCountry!C:C,0)) -> 6 | I70: Goldeneye | J70: =INDEX(TeamSports!B:B,MATCH(I70,TeamSports!C:C,0)) -> 43 | L70: =_xlfn.CONCAT($L$1,$P$1,$B$1,$P$1," ",$N$1,$C$2,$R$1,$D$2,$R$1,$F$2,$R$1,$H$2,$R$1,$J$2,$O$1,$M$1,$N$1,$Q$1,C70,$Q$1,$R$1,D70,$R$1,$L$2,$N$1,$Q$1,F70,$Q$1,$O$1,$R$1,H70,$R$1,J70,$O$1,$S$1) -> INSERT INTO "OlympicPlayers" (ol_player_name,ol_player_value,ol_player_image,ol_country_id,team_sport_id) VALUES ('Lee',1,pg_read_binary_file('E:\imagenes\personajes\goldeneye.png'),6,43);
B71: 69 | C71: Ken | D71: 1 | E71: \personajes\goldeneye.png | F71: =_xlfn.CONCAT($A$1,E71) -> E:\imagenes\personajes\goldeneye.png | G71: Lordena | H71: =INDEX(PlayerCountry!B:B,MATCH(G71,PlayerCountry!C:C,0)) -> 4 | I71: Goldeneye | J71: =INDEX(TeamSports!B:B,MATCH(I71,TeamSports!C:C,0)) -> 43 | L71: =_xlfn.CONCAT($L$1,$P$1,$B$1,$P$1," ",$N$1,$C$2,$R$1,$D$2,$R$1,$F$2,$R$1,$H$2,$R$1,$J$2,$O$1,$M$1,$N$1,$Q$1,C71,$Q$1,$R$1,D71,$R$1,$L$2,$N$1,$Q$1,F71,$Q$1,$O$1,$R$1,H71,$R$1,J71,$O$1,$S$1) -> INSERT INTO "OlympicPlayers" (ol_player_name,ol_player_value,ol_player_image,ol_country_id,team_sport_id) VALUES ('Ken',1,pg_read_binary_file('E:\imagenes\personajes\goldeneye.png'),4,43);
B72: 70 | C72: Karl | D72: 1 | E72: \personajes\goldeneye.png | F72: =_xlfn.CONCAT($A$1,E72) -> E:\imagenes\personajes\goldeneye.png | G72: Pokemonia | H72: =INDEX(PlayerCountry!B:B,MATCH(G72,PlayerCountry!C:C,0)) -> 5 | I72: Goldeneye | J72: =INDEX(TeamSports!B:B,MATCH(I72,TeamSports!C:C,0)) -> 43 | L72: =_xlfn.CONCAT($L$1,$P$1,$B$1,$P$1," ",$N$1,$C$2,$R$1,$D$2,$R$1,$F$2,$R$1,$H$2,$R$1,$J$2,$O$1,$M$1,$N$1,$Q$1,C72,$Q$1,$R$1,D72,$R$1,$L$2,$N$1,$Q$1,F72,$Q$1,$O$1,$R$1,H72,$R$1,J72,$O$1,$S$1) -> INSERT INTO "OlympicPlayers" (ol_player_name,ol_player_value,ol_player_image,ol_country_id,team_sport_id) VALUES ('Karl',1,pg_read_binary_file('E:\imagenes\personajes\goldeneye.png'),5,43);
... B451: 449 | C451: Pokemonia_MN | D451: 1 | E451: \personajes\olympics.png | F451: =_xlfn.CONCAT($A$1,E451) -> E:\imagenes\personajes\olympics.png | G451: Pokemonia | H451: =INDEX(PlayerCountry!B:B,MATCH(G451,PlayerCountry!C:C,0)) -> 5 | I451: Munecos | J451: =INDEX(TeamSports!B:B,MATCH(I451,TeamSports!C:C,0)) -> 46 | L451: =_xlfn.CONCAT($L$1,$P$1,$B$1,$P$1," ",$N$1,$C$2,$R$1,$D$2,$R$1,$F$2,$R$1,$H$2,$R$1,$J$2,$O$1,$M$1,$N$1,$Q$1,C451,$Q$1,$R$1,D451,$R$1,$L$2,$N$1,$Q$1,F451,$Q$1,$O$1,$R$1,H451,$R$1,J451,$O$1,$S$1) -> INSERT INTO "OlympicPlayers" (ol_player_name,ol_player_value,ol_player_image,ol_country_id,team_sport_id) VALUES ('Pokemonia_MN',1,pg_read_binary_file('E:\imagenes\personajes\olympics.png'),5,46);
B452: 450 | C452: Bowser_SSB | D452: 1 | E452: \personajes\bowser.png | F452: =_xlfn.CONCAT($A$1,E452) -> E:\imagenes\personajes\bowser.png | G452: Bollstam | H452: =INDEX(PlayerCountry!B:B,MATCH(G452,PlayerCountry!C:C,0)) -> 1 | I452: Mario Tenis | J452: 45 | L452: =_xlfn.CONCAT($L$1,$P$1,$B$1,$P$1," ",$N$1,$C$2,$R$1,$D$2,$R$1,$F$2,$R$1,$H$2,$R$1,$J$2,$O$1,$M$1,$N$1,$Q$1,C452,$Q$1,$R$1,D452,$R$1,$L$2,$N$1,$Q$1,F452,$Q$1,$O$1,$R$1,H452,$R$1,J452,$O$1,$S$1) -> INSERT INTO "OlympicPlayers" (ol_player_name,ol_player_value,ol_player_image,ol_country_id,team_sport_id) VALUES ('Bowser_SSB',1,pg_read_binary_file('E:\imagenes\personajes\bowser.png'),1,45);
B453: 451 | C453: Captain Falcon | D453: 1 | E453: =_xlfn.CONCAT("\personajes\",SUBSTITUTE(LOWER(C453)," ","_"),".png") -> \personajes\captain_falcon.png | F453: =_xlfn.CONCAT($A$1,E453) -> E:\imagenes\personajes\captain_falcon.png | G453: Bollstam | H453: =INDEX(PlayerCountry!B:B,MATCH(G453,PlayerCountry!C:C,0)) -> 1 | I453: F-Zero | J453: 45 | L453: =_xlfn.CONCAT($L$1,$P$1,$B$1,$P$1," ",$N$1,$C$2,$R$1,$D$2,$R$1,$F$2,$R$1,$H$2,$R$1,$J$2,$O$1,$M$1,$N$1,$Q$1,C453,$Q$1,$R$1,D453,$R$1,$L$2,$N$1,$Q$1,F453,$Q$1,$O$1,$R$1,H453,$R$1,J453,$O$1,$S$1) -> INSERT INTO "OlympicPlayers" (ol_player_name,ol_player_value,ol_player_image,ol_country_id,team_sport_id) VALUES ('Captain Falcon',1,pg_read_binary_file('E:\imagenes\personajes\captain_falcon.png'),1,45);
B454: 452 | C454: Samus/Samus | D454: 1 | E454: \personajes\samus.png | F454: =_xlfn.CONCAT($A$1,E454) -> E:\imagenes\personajes\samus.png | G454: Silnik | H454: =INDEX(PlayerCountry!B:B,MATCH(G454,PlayerCountry!C:C,0)) -> 8 | I454: Super Smash | J454: =INDEX(TeamSports!B:B,MATCH(I454,TeamSports!C:C,0)) -> 45 | L454: =_xlfn.CONCAT($L$1,$P$1,$B$1,$P$1," ",$N$1,$C$2,$R$1,$D$2,$R$1,$F$2,$R$1,$H$2,$R$1,$J$2,$O$1,$M$1,$N$1,$Q$1,C454,$Q$1,$R$1,D454,$R$1,$L$2,$N$1,$Q$1,F454,$Q$1,$O$1,$R$1,H454,$R$1,J454,$O$1,$S$1) -> INSERT INTO "OlympicPlayers" (ol_player_name,ol_player_value,ol_player_image,ol_country_id,team_sport_id) VALUES ('Samus/Samus',1,pg_read_binary_file('E:\imagenes\personajes\samus.png'),8,45);

Sheet PlayerCountry
B1: PlayerCountry | E1: INSERT INTO | F1: VALUES | G1: ( | H1: ) | I1: " | J1: ' | K1: , | L1: ;
B2: ol_country_id | C2: ol_country_name
B3: 1 | C3: Bollstam | E3: =_xlfn.CONCAT($E$1," ",$I$1,$B$1,$I$1," ",$G$1,$C$2,$H$1," ",$F$1," ",$G$1,$J$1,C3,$J$1,$H$1,$L$1) -> INSERT INTO "PlayerCountry" (ol_country_name) VALUES ('Bollstam');
B4: 2 | C4: Dinazor | E4: =_xlfn.CONCAT($E$1," ",$I$1,$B$1,$I$1," ",$G$1,$C$2,$H$1," ",$F$1," ",$G$1,$J$1,C4,$J$1,$H$1,$L$1) -> INSERT INTO "PlayerCountry" (ol_country_name) VALUES ('Dinazor');
B5: 3 | C5: Igra | E5: =_xlfn.CONCAT($E$1," ",$I$1,$B$1,$I$1," ",$G$1,$C$2,$H$1," ",$F$1," ",$G$1,$J$1,C5,$J$1,$H$1,$L$1) -> INSERT INTO "PlayerCountry" (ol_country_name) VALUES ('Igra');
B6: 4 | C6: Lordena | E6: =_xlfn.CONCAT($E$1," ",$I$1,$B$1,$I$1," ",$G$1,$C$2,$H$1," ",$F$1," ",$G$1,$J$1,C6,$J$1,$H$1,$L$1) -> INSERT INTO "PlayerCountry" (ol_country_name) VALUES ('Lordena');
B7: 5 | C7: Pokemonia | E7: =_xlfn.CONCAT($E$1," ",$I$1,$B$1,$I$1," ",$G$1,$C$2,$H$1," ",$F$1," ",$G$1,$J$1,C7,$J$1,$H$1,$L$1) -> INSERT INTO "PlayerCountry" (ol_country_name) VALUES ('Pokemonia');
B8: 6 | C8: Raimei | E8: =_xlfn.CONCAT($E$1," ",$I$1,$B$1,$I$1," ",$G$1,$C$2,$H$1," ",$F$1," ",$G$1,$J$1,C8,$J$1,$H$1,$L$1) -> INSERT INTO "PlayerCountry" (ol_country_name) VALUES ('Raimei');
B9: 7 | C9: Schattenmond | E9: =_xlfn.CONCAT($E$1," ",$I$1,$B$1,$I$1," ",$G$1,$C$2,$H$1," ",$F$1," ",$G$1,$J$1,C9,$J$1,$H$1,$L$1) -> INSERT INTO "PlayerCountry" (ol_country_name) VALUES ('Schattenmond');
B10: 8 | C10: Silnik | E10: =_xlfn.CONCAT($E$1," ",$I$1,$B$1,$I$1," ",$G$1,$C$2,$H$1," ",$F$1," ",$G$1,$J$1,C10,$J$1,$H$1,$L$1) -> INSERT INTO "PlayerCountry" (ol_country_name) VALUES ('Silnik');

Sheet Clubs
A1: E:\imagenes | B1: Clubs | O1: INSERT INTO | P1: VALUES | Q1: ( | R1: ) | S1: " | T1: ' | U1: , | V1: ;
B2: club_id | C2: club_name | D2: club_league | E2: club_league_id | I2: club_value | J2: ruta | K2: club_shield | L2: country | M2: club_country | O2: pg_read_binary_file
B3: 1 | C3: 07 Vestur | D3: Faroe Islands Premier League | E3: =INDEX(ClubLeague!B:B,MATCH(D3,ClubLeague!C:C,0)) -> 56 | F3: 57 | G3: 52 | H3: 45 | I3: =ROUND(AVERAGE(F3:H3),0) -> 51 | J3: \escudos_cl\Europa\Faroe Islands Premier League\07 Vestur.png | K3: =_xlfn.CONCAT($A$1,J3) -> E:\imagenes\escudos_cl\Europa\Faroe Islands Premier League\07 Vestur.png | L3: Islas Feroe | M3: =INDEX(NationalTeams!B:B,MATCH(L3,NationalTeams!C:C,0)) -> 103 | O3: =_xlfn.CONCAT($O$1,$S$1,$B$1,$S$1," ",$Q$1,$C$2,$U$1,$E$2,$U$1,$I$2,$U$1,$K$2,$U$1,$M$2,$R$1,$P$1,$Q$1,$T$1,C3,$T$1,$U$1,E3,$U$1,I3,$U$1,$O$2,$Q$1,$T$1,K3,$T$1,$R$1,$U$1,M3,$R$1,$V$1) -> INSERT INTO "Clubs" (club_name,club_league_id,club_value,club_shield,club_country) VALUES ('07 Vestur',56,51,pg_read_binary_file('E:\imagenes\escudos_cl\Europa\Faroe Islands Premier League\07 Vestur.png'),103);
B4: 2 | C4: 1.FC Kaiserslautern | D4: 2. Bundesliga | E4: =INDEX(ClubLeague!B:B,MATCH(D4,ClubLeague!C:C,0)) -> 2 | F4: 65 | G4: 65 | H4: 69 | I4: =ROUND(AVERAGE(F4:H4),0) -> 66 | J4: \escudos_cl\Europa\2. Bundesliga\1.FC Kaiserslautern.png | K4: =_xlfn.CONCAT($A$1,J4) -> E:\imagenes\escudos_cl\Europa\2. Bundesliga\1.FC Kaiserslautern.png | L4: Alemania | M4: =INDEX(NationalTeams!B:B,MATCH(L4,NationalTeams!C:C,0)) -> 4 | O4: =_xlfn.CONCAT($O$1,$S$1,$B$1,$S$1," ",$Q$1,$C$2,$U$1,$E$2,$U$1,$I$2,$U$1,$K$2,$U$1,$M$2,$R$1,$P$1,$Q$1,$T$1,C4,$T$1,$U$1,E4,$U$1,I4,$U$1,$O$2,$Q$1,$T$1,K4,$T$1,$R$1,$U$1,M4,$R$1,$V$1) -> INSERT INTO "Clubs" (club_name,club_league_id,club_value,club_shield,club_country) VALUES ('1.FC Kaiserslautern',2,66,pg_read_binary_file('E:\imagenes\escudos_cl\Europa\2. Bundesliga\1.FC Kaiserslautern.png'),4);
B5: 3 | C5: 1.SK Prostejov | D5: Czech National Football League | E5: =INDEX(ClubLeague!B:B,MATCH(D5,ClubLeague!C:C,0)) -> 42 | F5: 47 | G5: 57 | H5: 51 | I5: =ROUND(AVERAGE(F5:H5),0) -> 52 | J5: \escudos_cl\Europa\Czech National Football League\1.SK Prostejov.png | K5: =_xlfn.CONCAT($A$1,J5) -> E:\imagenes\escudos_cl\Europa\Czech National Football League\1.SK Prostejov.png | L5: Republica Checa | M5: =INDEX(NationalTeams!B:B,MATCH(L5,NationalTeams!C:C,0)) -> 171 | O5: =_xlfn.CONCAT($O$1,$S$1,$B$1,$S$1," ",$Q$1,$C$2,$U$1,$E$2,$U$1,$I$2,$U$1,$K$2,$U$1,$M$2,$R$1,$P$1,$Q$1,$T$1,C5,$T$1,$U$1,E5,$U$1,I5,$U$1,$O$2,$Q$1,$T$1,K5,$T$1,$R$1,$U$1,M5,$R$1,$V$1) -> INSERT INTO "Clubs" (club_name,club_league_id,club_value,club_shield,club_country) VALUES ('1.SK Prostejov',42,52,pg_read_binary_file('E:\imagenes\escudos_cl\Europa\Czech National Football League\1.SK Prostejov.png'),171);
B6: 4 | C6: 22 de Julio FC | D6: LigaPro Ecuabet Serie B | E6: =INDEX(ClubLeague!B:B,MATCH(D6,ClubLeague!C:C,0)) -> 112 | F6: 58 | G6: 58 | H6: 58 | I6: =ROUND(AVERAGE(F6:H6),0) -> 58 | J6: \escudos_cl\America\LigaPro Ecuabet Serie B\22 de Julio FC.png | K6: =_xlfn.CONCAT($A$1,J6) -> E:\imagenes\escudos_cl\America\LigaPro Ecuabet Serie B\22 de Julio FC.png | L6: Ecuador | M6: =INDEX(NationalTeams!B:B,MATCH(L6,NationalTeams!C:C,0)) -> 58 | O6: =_xlfn.CONCAT($O$1,$S$1,$B$1,$S$1," ",$Q$1,$C$2,$U$1,$E$2,$U$1,$I$2,$U$1,$K$2,$U$1,$M$2,$R$1,$P$1,$Q$1,$T$1,C6,$T$1,$U$1,E6,$U$1,I6,$U$1,$O$2,$Q$1,$T$1,K6,$T$1,$R$1,$U$1,M6,$R$1,$V$1) -> INSERT INTO "Clubs" (club_name,club_league_id,club_value,club_shield,club_country) VALUES ('22 de Julio FC',112,58,pg_read_binary_file('E:\imagenes\escudos_cl\America\LigaPro Ecuabet Serie B\22 de Julio FC.png'),58);
B7: 5 | C7: 9 de Octubre FC | D7: LigaPro Ecuabet Serie B | E7: =INDEX(ClubLeague!B:B,MATCH(D7,ClubLeague!C:C,0)) -> 112 | F7: 58 | G7: 56 | H7: 59 | I7: =ROUND(AVERAGE(F7:H7),0) -> 58 | J7: \escudos_cl\America\LigaPro Ecuabet Serie B\9 de Octubre FC.png | K7: =_xlfn.CONCAT($A$1,J7) -> E:\imagenes\escudos_cl\America\LigaPro Ecuabet Serie B\9 de Octubre FC.png | L7: Ecuador | M7: =INDEX(NationalTeams!B:B,MATCH(L7,NationalTeams!C:C,0)) -> 58 | O7: =_xlfn.CONCAT($O$1,$S$1,$B$1,$S$1," ",$Q$1,$C$2,$U$1,$E$2,$U$1,$I$2,$U$1,$K$2,$U$1,$M$2,$R$1,$P$1,$Q$1,$T$1,C7,$T$1,$U$1,E7,$U$1,I7,$U$1,$O$2,$Q$1,$T$1,K7,$T$1,$R$1,$U$1,M7,$R$1,$V$1) -> INSERT INTO "Clubs" (club_name,club_league_id,club_value,club_shield,club_country) VALUES ('9 de Octubre FC',112,58,pg_read_binary_file('E:\imagenes\escudos_cl\America\LigaPro Ecuabet Serie B\9 de Octubre FC.png'),58);
B8: 6 | C8: Aalesunds FK | D8: Norwegian First Division | E8: =INDEX(ClubLeague!B:B,MATCH(D8,ClubLeague!C:C,0)) -> 141 | F8: 55 | G8: 58 | H8: 54 | I8: =ROUND(AVERAGE(F8:H8),0) -> 56 | J8: \escudos_cl\Europa\Norwegian First Division\Aalesunds FK.png | K8: =_xlfn.CONCAT($A$1,J8) -> E:\imagenes\escudos_cl\Europa\Norwegian First Division\Aalesunds FK.png | L8: Noruega | M8: =INDEX(NationalTeams!B:B,MATCH(L8,NationalTeams!C:C,0)) -> 154 | O8: =_xlfn.CONCAT($O$1,$S$1,$B$1,$S$1," ",$Q$1,$C$2,$U$1,$E$2,$U$1,$I$2,$U$1,$K$2,$U$1,$M$2,$R$1,$P$1,$Q$1,$T$1,C8,$T$1,$U$1,E8,$U$1,I8,$U$1,$O$2,$Q$1,$T$1,K8,$T$1,$R$1,$U$1,M8,$R$1,$V$1) -> INSERT INTO "Clubs" (club_name,club_league_id,club_value,club_shield,club_country) VALUES ('Aalesunds FK',141,56,pg_read_binary_file('E:\imagenes\escudos_cl\Europa\Norwegian First Division\Aalesunds FK.png'),154);
B9: 7 | C9: Aali CSC | D9: Bahrain Premier League | E9: =INDEX(ClubLeague!B:B,MATCH(D9,ClubLeague!C:C,0)) -> 17 | F9: 56 | G9: 59 | H9: 55 | I9: =ROUND(AVERAGE(F9:H9),0) -> 57 | J9: \escudos_cl\Asia\Bahrain Premier League\Aali CSC.png | K9: =_xlfn.CONCAT($A$1,J9) -> E:\imagenes\escudos_cl\Asia\Bahrain Premier League\Aali CSC.png | L9: Bahrein | M9: =INDEX(NationalTeams!B:B,MATCH(L9,NationalTeams!C:C,0)) -> 20 | O9: =_xlfn.CONCAT($O$1,$S$1,$B$1,$S$1," ",$Q$1,$C$2,$U$1,$E$2,$U$1,$I$2,$U$1,$K$2,$U$1,$M$2,$R$1,$P$1,$Q$1,$T$1,C9,$T$1,$U$1,E9,$U$1,I9,$U$1,$O$2,$Q$1,$T$1,K9,$T$1,$R$1,$U$1,M9,$R$1,$V$1) -> INSERT INTO "Clubs" (club_name,club_league_id,club_value,club_shield,club_country) VALUES ('Aali CSC',17,57,pg_read_binary_file('E:\imagenes\escudos_cl\Asia\Bahrain Premier League\Aali CSC.png'),20);
B10: 8 | C10: Aarhus GF | D10: 3F Superliga | E10: =INDEX(ClubLeague!B:B,MATCH(D10,ClubLeague!C:C,0)) -> 5 | F10: 52 | G10: 64 | H10: 59 | I10: =ROUND(AVERAGE(F10:H10),0) -> 58 | J10: \escudos_cl\Europa\3F Superliga\Aarhus GF.png | K10: =_xlfn.CONCAT($A$1,J10) -> E:\imagenes\escudos_cl\Europa\3F Superliga\Aarhus GF.png | L10: Dinamarca | M10: =INDEX(NationalTeams!B:B,MATCH(L10,NationalTeams!C:C,0)) -> 56 | O10: =_xlfn.CONCAT($O$1,$S$1,$B$1,$S$1," ",$Q$1,$C$2,$U$1,$E$2,$U$1,$I$2,$U$1,$K$2,$U$1,$M$2,$R$1,$P$1,$Q$1,$T$1,C10,$T$1,$U$1,E10,$U$1,I10,$U$1,$O$2,$Q$1,$T$1,K10,$T$1,$R$1,$U$1,M10,$R$1,$V$1) -> INSERT INTO "Clubs" (club_name,club_league_id,club_value,club_shield,club_country) VALUES ('Aarhus GF',5,58,pg_read_binary_file('E:\imagenes\escudos_cl\Europa\3F Superliga\Aarhus GF.png'),56);
B11: 9 | C11: Abahani Limited Dhaka | D11: Bangladesh Premier League | E11: =INDEX(ClubLeague!B:B,MATCH(D11,ClubLeague!C:C,0)) -> 18 | F11: 48 | G11: 48 | H11: 53 | I11: =ROUND(AVERAGE(F11:H11),0) -> 50 | J11: \escudos_cl\Asia\Bangladesh Premier League\Abahani Limited Dhaka.png | K11: =_xlfn.CONCAT($A$1,J11) -> E:\imagenes\escudos_cl\Asia\Bangladesh Premier League\Abahani Limited Dhaka.png | L11: Bangladesh | M11: =INDEX(NationalTeams!B:B,MATCH(L11,NationalTeams!C:C,0)) -> 21 | O11: =_xlfn.CONCAT($O$1,$S$1,$B$1,$S$1," ",$Q$1,$C$2,$U$1,$E$2,$U$1,$I$2,$U$1,$K$2,$U$1,$M$2,$R$1,$P$1,$Q$1,$T$1,C11,$T$1,$U$1,E11,$U$1,I11,$U$1,$O$2,$Q$1,$T$1,K11,$T$1,$R$1,$U$1,M11,$R$1,$V$1) -> INSERT INTO "Clubs" (club_name,club_league_id,club_value,club_shield,club_country) VALUES ('Abahani Limited Dhaka',18,50,pg_read_binary_file('E:\imagenes\escudos_cl\Asia\Bangladesh Premier League\Abahani Limited Dhaka.png'),21);
B12: 10 | C12: Aberdeen FC | D12: Scottish Premiership | E12: =INDEX(ClubLeague!B:B,MATCH(D12,ClubLeague!C:C,0)) -> 163 | F12: 63 | G12: 66 | H12: 63 | I12: =ROUND(AVERAGE(F12:H12),0) -> 64 | J12: \escudos_cl\Europa\Scottish Premiership\Aberdeen FC.png | K12: =_xlfn.CONCAT($A$1,J12) -> E:\imagenes\escudos_cl\Europa\Scottish Premiership\Aberdeen FC.png | L12: Escocia | M12: =INDEX(NationalTeams!B:B,MATCH(L12,NationalTeams!C:C,0)) -> 63 | O12: =_xlfn.CONCAT($O$1,$S$1,$B$1,$S$1," ",$Q$1,$C$2,$U$1,$E$2,$U$1,$I$2,$U$1,$K$2,$U$1,$M$2,$R$1,$P$1,$Q$1,$T$1,C12,$T$1,$U$1,E12,$U$1,I12,$U$1,$O$2,$Q$1,$T$1,K12,$T$1,$R$1,$U$1,M12,$R$1,$V$1) -> INSERT INTO "Clubs" (club_name,club_league_id,club_value,club_shield,club_country) VALUES ('Aberdeen FC',163,64,pg_read_binary_file('E:\imagenes\escudos_cl\Europa\Scottish Premiership\Aberdeen FC.png'),63);
B13: 11 | C13: Aberstwyth Town FC | D13: Cymru Second | E13: =INDEX(ClubLeague!B:B,MATCH(D13,ClubLeague!C:C,0)) -> 37 | F13: 58 | G13: 56 | H13: 55 | I13: =ROUND(AVERAGE(F13:H13),0) -> 56 | J13: \escudos_cl\Europa\Cymru South\Aberstwyth Town FC.png | K13: =_xlfn.CONCAT($A$1,J13) -> E:\imagenes\escudos_cl\Europa\Cymru South\Aberstwyth Town FC.png | L13: Gales | M13: =INDEX(NationalTeams!B:B,MATCH(L13,NationalTeams!C:C,0)) -> 76 | O13: =_xlfn.CONCAT($O$1,$S$1,$B$1,$S$1," ",$Q$1,$C$2,$U$1,$E$2,$U$1,$I$2,$U$1,$K$2,$U$1,$M$2,$R$1,$P$1,$Q$1,$T$1,C13,$T$1,$U$1,E13,$U$1,I13,$U$1,$O$2,$Q$1,$T$1,K13,$T$1,$R$1,$U$1,M13,$R$1,$V$1) -> INSERT INTO "Clubs" (club_name,club_league_id,club_value,club_shield,club_country) VALUES ('Aberstwyth Town FC',37,56,pg_read_binary_file('E:\imagenes\escudos_cl\Europa\Cymru South\Aberstwyth Town FC.png'),76);
B14: 12 | C14: Abha FC | D14: FD League | E14: =INDEX(ClubLeague!B:B,MATCH(D14,ClubLeague!C:C,0)) -> 57 | F14: 62 | G14: 57 | H14: 59 | I14: =ROUND(AVERAGE(F14:H14),0) -> 59 | J14: \escudos_cl\Asia\FD League\Abha FC.png | K14: =_xlfn.CONCAT($A$1,J14) -> E:\imagenes\escudos_cl\Asia\FD League\Abha FC.png | L14: Arabia Saudita | M14: =INDEX(NationalTeams!B:B,MATCH(L14,NationalTeams!C:C,0)) -> 10 | O14: =_xlfn.CONCAT($O$1,$S$1,$B$1,$S$1," ",$Q$1,$C$2,$U$1,$E$2,$U$1,$I$2,$U$1,$K$2,$U$1,$M$2,$R$1,$P$1,$Q$1,$T$1,C14,$T$1,$U$1,E14,$U$1,I14,$U$1,$O$2,$Q$1,$T$1,K14,$T$1,$R$1,$U$1,M14,$R$1,$V$1) -> INSERT INTO "Clubs" (club_name,club_league_id,club_value,club_shield,club_country) VALUES ('Abha FC',57,59,pg_read_binary_file('E:\imagenes\escudos_cl\Asia\FD League\Abha FC.png'),10);
... B3037: 3035 | C3037: ZPC Kariba FC | D3037: Zimbabwe Premier Soccer League | E3037: =INDEX(ClubLeague!B:B,MATCH(D3037,ClubLeague!C:C,0)) -> 211 | F3037: 49 | G3037: 54 | H3037: 49 | I3037: =ROUND(AVERAGE(F3037:H3037),0) -> 51 | J3037: \escudos_cl\Africa\Zimbabwe Premier Soccer League\ZPC Kariba FC.png | K3037: =_xlfn.CONCAT($A$1,J3037) -> E:\imagenes\escudos_cl\Africa\Zimbabwe Premier Soccer League\ZPC Kariba FC.png | L3037: Zimbaue | M3037: =INDEX(NationalTeams!B:B,MATCH(L3037,NationalTeams!C:C,0)) -> 223 | O3037: =_xlfn.CONCAT($O$1,$S$1,$B$1,$S$1," ",$Q$1,$C$2,$U$1,$E$2,$U$1,$I$2,$U$1,$K$2,$U$1,$M$2,$R$1,$P$1,$Q$1,$T$1,C3037,$T$1,$U$1,E3037,$U$1,I3037,$U$1,$O$2,$Q$1,$T$1,K3037,$T$1,$R$1,$U$1,M3037,$R$1,$V$1) -> INSERT INTO "Clubs" (club_name,club_league_id,club_value,club_shield,club_country) VALUES ('ZPC Kariba FC',211,51,pg_read_binary_file('E:\imagenes\escudos_cl\Africa\Zimbabwe Premier Soccer League\ZPC Kariba FC.png'),223);

Sheet ClubLeague
B1: ClubLeague | O1: INSERT INTO | P1: VALUES | Q1: ( | R1: ) | S1: " | T1: ' | U1: , | V1: ;
B2: club_league_id | C2: club_league_name | D2: club_country | E2: Region | F2: team_region_id | G2: club_country | H2: club_division | I2: club_prom_reg | J2: club_first_qual | K2: club_second_qual | L2: club_third_qual | M2: clas_direct
B3: 1 | C3: 1. Deild Karla | D3: Islandia | E3: Europa | F3: =INDEX(TeamRegion!B:B,MATCH(E3,TeamRegion!C:C,0)) -> 4 | G3: =INDEX(NationalTeams!B:B,MATCH(D3,NationalTeams!C:C,0)) -> 100 | H3: 2D | I3: 2 | J3: 0 | K3: 0 | L3: 0 | M3: N | O3: =_xlfn.CONCAT($O$1," ",$S$1,$B$1,$S$1," ",$Q$1,$C$2,$U$1,$F$2,$U$1,$G$2,$U$1,$H$2,$U$1,$I$2,$U$1,$J$2,$U$1,$K$2,$U$1,$L$2,$U$1,$M$2,$R$1,$P$1,$Q$1,$T$1,C3,$T$1,$U$1,F3,$U$1,G3,$U$1,$T$1,H3,$T$1,$U$1,I3,$U$1,J3,$U$1,K3,$U$1,L3,$U$1,$T$1,M3,$T$1,$R$1,$V$1) -> INSERT INTO "ClubLeague" (club_league_name,team_region_id,club_country,club_division,club_prom_reg,club_first_qual,club_second_qual,club_third_qual,clas_direct) VALUES ('1. Deild Karla',4,100,'2D',2,0,0,0,'N');
B4: 2 | C4: 2. Bundesliga | D4: Alemania | E4: Europa | F4: =INDEX(TeamRegion!B:B,MATCH(E4,TeamRegion!C:C,0)) -> 4 | G4: =INDEX(NationalTeams!B:B,MATCH(D4,NationalTeams!C:C,0)) -> 4 | H4: 2D | I4: 2 | J4: 0 | K4: 0 | L4: 0 | M4: N | O4: =_xlfn.CONCAT($O$1," ",$S$1,$B$1,$S$1," ",$Q$1,$C$2,$U$1,$F$2,$U$1,$G$2,$U$1,$H$2,$U$1,$I$2,$U$1,$J$2,$U$1,$K$2,$U$1,$L$2,$U$1,$M$2,$R$1,$P$1,$Q$1,$T$1,C4,$T$1,$U$1,F4,$U$1,G4,$U$1,$T$1,H4,$T$1,$U$1,I4,$U$1,J4,$U$1,K4,$U$1,L4,$U$1,$T$1,M4,$T$1,$R$1,$V$1) -> INSERT INTO "ClubLeague" (club_league_name,team_region_id,club_country,club_division,club_prom_reg,club_first_qual,club_second_qual,club_third_qual,clas_direct) VALUES ('2. Bundesliga',4,4,'2D',2,0,0,0,'N');
B5: 3 | C5: 2. HNL 2024-25 | D5: Croacia | E5: Europa | F5: =INDEX(TeamRegion!B:B,MATCH(E5,TeamRegion!C:C,0)) -> 4 | G5: =INDEX(NationalTeams!B:B,MATCH(D5,NationalTeams!C:C,0)) -> 53 | H5: 2D | I5: 2 | J5: 0 | K5: 0 | L5: 0 | M5: N | O5: =_xlfn.CONCAT($O$1," ",$S$1,$B$1,$S$1," ",$Q$1,$C$2,$U$1,$F$2,$U$1,$G$2,$U$1,$H$2,$U$1,$I$2,$U$1,$J$2,$U$1,$K$2,$U$1,$L$2,$U$1,$M$2,$R$1,$P$1,$Q$1,$T$1,C5,$T$1,$U$1,F5,$U$1,G5,$U$1,$T$1,H5,$T$1,$U$1,I5,$U$1,J5,$U$1,K5,$U$1,L5,$U$1,$T$1,M5,$T$1,$R$1,$V$1) -> INSERT INTO "ClubLeague" (club_league_name,team_region_id,club_country,club_division,club_prom_reg,club_first_qual,club_second_qual,club_third_qual,clas_direct) VALUES ('2. HNL 2024-25',4,53,'2D',2,0,0,0,'N');
B6: 4 | C6: 2. Liga | D6: Austria | E6: Europa | F6: =INDEX(TeamRegion!B:B,MATCH(E6,TeamRegion!C:C,0)) -> 4 | G6: =INDEX(NationalTeams!B:B,MATCH(D6,NationalTeams!C:C,0)) -> 17 | H6: 2D | I6: 2 | J6: 0 | K6: 0 | L6: 0 | M6: N | O6: =_xlfn.CONCAT($O$1," ",$S$1,$B$1,$S$1," ",$Q$1,$C$2,$U$1,$F$2,$U$1,$G$2,$U$1,$H$2,$U$1,$I$2,$U$1,$J$2,$U$1,$K$2,$U$1,$L$2,$U$1,$M$2,$R$1,$P$1,$Q$1,$T$1,C6,$T$1,$U$1,F6,$U$1,G6,$U$1,$T$1,H6,$T$1,$U$1,I6,$U$1,J6,$U$1,K6,$U$1,L6,$U$1,$T$1,M6,$T$1,$R$1,$V$1) -> INSERT INTO "ClubLeague" (club_league_name,team_region_id,club_country,club_division,club_prom_reg,club_first_qual,club_second_qual,club_third_qual,clas_direct) VALUES ('2. Liga',4,17,'2D',2,0,0,0,'N');
B7: 5 | C7: 3F Superliga | D7: Dinamarca | E7: Europa | F7: =INDEX(TeamRegion!B:B,MATCH(E7,TeamRegion!C:C,0)) -> 4 | G7: =INDEX(NationalTeams!B:B,MATCH(D7,NationalTeams!C:C,0)) -> 56 | H7: 1D | I7: 2 | J7: 1 | K7: 1 | L7: 1 | M7: Y | O7: =_xlfn.CONCAT($O$1," ",$S$1,$B$1,$S$1," ",$Q$1,$C$2,$U$1,$F$2,$U$1,$G$2,$U$1,$H$2,$U$1,$I$2,$U$1,$J$2,$U$1,$K$2,$U$1,$L$2,$U$1,$M$2,$R$1,$P$1,$Q$1,$T$1,C7,$T$1,$U$1,F7,$U$1,G7,$U$1,$T$1,H7,$T$1,$U$1,I7,$U$1,J7,$U$1,K7,$U$1,L7,$U$1,$T$1,M7,$T$1,$R$1,$V$1) -> INSERT INTO "ClubLeague" (club_league_name,team_region_id,club_country,club_division,club_prom_reg,club_first_qual,club_second_qual,club_third_qual,clas_direct) VALUES ('3F Superliga',4,56,'1D',2,1,1,1,'Y');
B8: 6 | C8: A League | D8: Australia | E8: Asia | F8: =INDEX(TeamRegion!B:B,MATCH(E8,TeamRegion!C:C,0)) -> 2 | G8: =INDEX(NationalTeams!B:B,MATCH(D8,NationalTeams!C:C,0)) -> 16 | H8: 1D | I8: 2 | J8: 1 | K8: 1 | L8: 0 | M8: Y | O8: =_xlfn.CONCAT($O$1," ",$S$1,$B$1,$S$1," ",$Q$1,$C$2,$U$1,$F$2,$U$1,$G$2,$U$1,$H$2,$U$1,$I$2,$U$1,$J$2,$U$1,$K$2,$U$1,$L$2,$U$1,$M$2,$R$1,$P$1,$Q$1,$T$1,C8,$T$1,$U$1,F8,$U$1,G8,$U$1,$T$1,H8,$T$1,$U$1,I8,$U$1,J8,$U$1,K8,$U$1,L8,$U$1,$T$1,M8,$T$1,$R$1,$V$1) -> INSERT INTO "ClubLeague" (club_league_name,team_region_id,club_country,club_division,club_prom_reg,club_first_qual,club_second_qual,club_third_qual,clas_direct) VALUES ('A League',2,16,'1D',2,1,1,0,'Y');
B9: 7 | C9: A Lyga | D9: Lituania | E9: Europa | F9: =INDEX(TeamRegion!B:B,MATCH(E9,TeamRegion!C:C,0)) -> 4 | G9: =INDEX(NationalTeams!B:B,MATCH(D9,NationalTeams!C:C,0)) -> 127 | H9: 1D | I9: 2 | J9: 1 | K9: 0 | L9: 1 | M9: N | O9: =_xlfn.CONCAT($O$1," ",$S$1,$B$1,$S$1," ",$Q$1,$C$2,$U$1,$F$2,$U$1,$G$2,$U$1,$H$2,$U$1,$I$2,$U$1,$J$2,$U$1,$K$2,$U$1,$L$2,$U$1,$M$2,$R$1,$P$1,$Q$1,$T$1,C9,$T$1,$U$1,F9,$U$1,G9,$U$1,$T$1,H9,$T$1,$U$1,I9,$U$1,J9,$U$1,K9,$U$1,L9,$U$1,$T$1,M9,$T$1,$R$1,$V$1) -> INSERT INTO "ClubLeague" (club_league_name,team_region_id,club_country,club_division,club_prom_reg,club_first_qual,club_second_qual,club_third_qual,clas_direct) VALUES ('A Lyga',4,127,'1D',2,1,0,1,'N');
B10: 8 | C10: Abissnet Superiore | D10: Albania | E10: Europa | F10: =INDEX(TeamRegion!B:B,MATCH(E10,TeamRegion!C:C,0)) -> 4 | G10: =INDEX(NationalTeams!B:B,MATCH(D10,NationalTeams!C:C,0)) -> 3 | H10: 1D | I10: 2 | J10: 1 | K10: 1 | L10: 1 | M10: N | O10: =_xlfn.CONCAT($O$1," ",$S$1,$B$1,$S$1," ",$Q$1,$C$2,$U$1,$F$2,$U$1,$G$2,$U$1,$H$2,$U$1,$I$2,$U$1,$J$2,$U$1,$K$2,$U$1,$L$2,$U$1,$M$2,$R$1,$P$1,$Q$1,$T$1,C10,$T$1,$U$1,F10,$U$1,G10,$U$1,$T$1,H10,$T$1,$U$1,I10,$U$1,J10,$U$1,K10,$U$1,L10,$U$1,$T$1,M10,$T$1,$R$1,$V$1) -> INSERT INTO "ClubLeague" (club_league_name,team_region_id,club_country,club_division,club_prom_reg,club_first_qual,club_second_qual,club_third_qual,clas_direct) VALUES ('Abissnet Superiore',4,3,'1D',2,1,1,1,'N');
B11: 9 | C11: Admiral Bundesliga | D11: Austria | E11: Europa | F11: =INDEX(TeamRegion!B:B,MATCH(E11,TeamRegion!C:C,0)) -> 4 | G11: =INDEX(NationalTeams!B:B,MATCH(D11,NationalTeams!C:C,0)) -> 17 | H11: 1D | I11: 2 | J11: 1 | K11: 2 | L11: 1 | M11: Y | O11: =_xlfn.CONCAT($O$1," ",$S$1,$B$1,$S$1," ",$Q$1,$C$2,$U$1,$F$2,$U$1,$G$2,$U$1,$H$2,$U$1,$I$2,$U$1,$J$2,$U$1,$K$2,$U$1,$L$2,$U$1,$M$2,$R$1,$P$1,$Q$1,$T$1,C11,$T$1,$U$1,F11,$U$1,G11,$U$1,$T$1,H11,$T$1,$U$1,I11,$U$1,J11,$U$1,K11,$U$1,L11,$U$1,$T$1,M11,$T$1,$R$1,$V$1) -> INSERT INTO "ClubLeague" (club_league_name,team_region_id,club_country,club_division,club_prom_reg,club_first_qual,club_second_qual,club_third_qual,clas_direct) VALUES ('Admiral Bundesliga',4,17,'1D',2,1,2,1,'Y');
B12: 10 | C12: Algerian Ligue 2 | D12: Argelia | E12: Africa | F12: =INDEX(TeamRegion!B:B,MATCH(E12,TeamRegion!C:C,0)) -> 1 | G12: =INDEX(NationalTeams!B:B,MATCH(D12,NationalTeams!C:C,0)) -> 11 | H12: 2D | I12: 2 | J12: 0 | K12: 0 | L12: 0 | M12: N | O12: =_xlfn.CONCAT($O$1," ",$S$1,$B$1,$S$1," ",$Q$1,$C$2,$U$1,$F$2,$U$1,$G$2,$U$1,$H$2,$U$1,$I$2,$U$1,$J$2,$U$1,$K$2,$U$1,$L$2,$U$1,$M$2,$R$1,$P$1,$Q$1,$T$1,C12,$T$1,$U$1,F12,$U$1,G12,$U$1,$T$1,H12,$T$1,$U$1,I12,$U$1,J12,$U$1,K12,$U$1,L12,$U$1,$T$1,M12,$T$1,$R$1,$V$1) -> INSERT INTO "ClubLeague" (club_league_name,team_region_id,club_country,club_division,club_prom_reg,club_first_qual,club_second_qual,club_third_qual,clas_direct) VALUES ('Algerian Ligue 2',1,11,'2D',2,0,0,0,'N');
